<sdf version='1.6'>
  <model name='flyant'>
  <pose>0 0 0.1 0 0 0</pose>
    <link name='base_link'>
      <pose>0 0 0 0 0 0</pose>
      <inertial>
        <pose>0 0 0 0 0 0</pose>
        <mass>1.5</mass>
        <inertia>
          <ixx>0.0025</ixx>
          <ixy>0</ixy>
          <ixz>0</ixz>
          <iyy>0.0025</iyy>
          <iyz>0</iyz>
          <izz>0.0025</izz>
        </inertia>
      </inertial>
      <collision name='base_link_inertia_collision'>
        <pose>0 0 0 0 0 0</pose>
        <geometry>
          <box>
            <size>0.1 0.1 0.1</size>
          </box>
        </geometry>
      </collision>
      <visual name='base_link_inertia_visual'>
        <pose>0 0 0 0 0 0</pose>
        <geometry>
          <box>
            <size>0.1 0.1 0.1</size>
          </box>
        </geometry>
        <material>
          <script>
            <name>Gazebo/DarkGrey</name>
            <uri>file://media/materials/scripts/gazebo.material</uri>
          </script>
        </material>
      </visual>
      <gravity>1</gravity>
      <velocity_decay/>
    </link>
    <link name='link_1'>
      <inertial>
        <mass>0.01</mass>
        <inertia>
          <ixx>1.3358e-04</ixx>
          <ixy>0.0</ixy>
          <iyy>1.3358e-04</iyy>
          <ixz>0.0</ixz>
          <iyz>0.0</iyz>
          <izz>5.0000e-07</izz>
        </inertia>
      </inertial>
      <pose>0 -0 0.08 1.57 -0 0</pose>
      <visual name='visual'>
        <pose>0 0 0 0 -0 0</pose>
        <geometry>
          <cylinder>
            <radius>0.01</radius>
            <length>0.4</length>
          </cylinder>
        </geometry>
      </visual>
    </link>
    <link name='link_4'>
      <inertial>
        <mass>0.005</mass>
        <inertia>
          <ixx>7.9167e-07</ixx>
          <ixy>0.0</ixy>
          <iyy>7.9167e-07</iyy>
          <ixz>0.0</ixz>
          <iyz>0.0</iyz>
          <izz>2.5000e-07</izz>
        </inertia>
      </inertial>
      <pose>0 0 0.06 -0 -0 -0</pose>
      <gravity>1</gravity>
      <self_collide>0</self_collide>
      <kinematic>0</kinematic>
      <enable_wind>0</enable_wind>
      <visual name='visual'>
        <pose>0 0 0 0 -0 0</pose>
        <geometry>
          <cylinder>
            <radius>0.01</radius>
            <length>0.04</length>
          </cylinder>
        </geometry>
        <material>
          <lighting>1</lighting>
          <script>
            <uri>file://media/materials/scripts/gazebo.material</uri>
            <name>Gazebo/Grey</name>
          </script>
          <shader type='pixel'>
            <normal_map>__default__</normal_map>
          </shader>
          <ambient>0.3 0.3 0.3 1</ambient>
          <diffuse>0.7 0.7 0.7 1</diffuse>
          <specular>0.01 0.01 0.01 1</specular>
          <emissive>0 0 0 1</emissive>
        </material>
        <transparency>0</transparency>
        <cast_shadows>1</cast_shadows>
      </visual>
    </link>
    <link name='link_2'>
      <inertial>
        <mass>0.1</mass>
        <inertia>
          <ixx>1.8958e-05</ixx>
          <ixy>0.0</ixy>
          <iyy>1.8958e-05</iyy>
          <ixz>0.0</ixz>
          <iyz>0.0</iyz>
          <izz>1.1250e-05</izz>
        </inertia>
      </inertial>
      <pose>0 0.2 0.08 -0 -0 -0</pose>
      <gravity>1</gravity>
      <self_collide>0</self_collide>
      <kinematic>0</kinematic>
      <enable_wind>0</enable_wind>
      <visual name='visual'>
        <pose>0 0 0 0 -0 0</pose>
        <geometry>
          <cylinder>
            <radius>0.015</radius>
            <length>0.04</length>
          </cylinder>
        </geometry>
        <material>
          <lighting>1</lighting>
          <script>
            <uri>file://media/materials/scripts/gazebo.material</uri>
            <name>Gazebo/Grey</name>
          </script>
          <shader type='pixel'>
            <normal_map>__default__</normal_map>
          </shader>
          <ambient>0.3 0.3 0.3 1</ambient>
          <diffuse>0.7 0.7 0.7 1</diffuse>
          <specular>0.01 0.01 0.01 1</specular>
          <emissive>0 0 0 1</emissive>
        </material>
        <transparency>0</transparency>
        <cast_shadows>1</cast_shadows>
      </visual>
    </link>

    <link name='link_3'>
      <inertial>
        <mass>0.1</mass>
        <inertia>
          <ixx>1.8958e-05</ixx>
          <ixy>0.0</ixy>
          <iyy>1.8958e-05</iyy>
          <ixz>0.0</ixz>
          <iyz>0.0</iyz>
          <izz>1.1250e-05</izz>
        </inertia>
      </inertial>
      <pose>0 -0.2 0.080 -0.00178 1e-06 0</pose>
      <gravity>1</gravity>
      <self_collide>0</self_collide>
      <kinematic>0</kinematic>
      <enable_wind>0</enable_wind>
      <visual name='visual'>
        <pose>0 0 0 0 -0 0</pose>
        <geometry>
          <cylinder>
            <radius>0.015</radius>
            <length>0.04</length>
          </cylinder>
        </geometry>
        <material>
          <lighting>1</lighting>
          <script>
            <uri>file://media/materials/scripts/gazebo.material</uri>
            <name>Gazebo/Grey</name>
          </script>
          <shader type='pixel'>
            <normal_map>__default__</normal_map>
          </shader>
          <ambient>0.3 0.3 0.3 1</ambient>
          <diffuse>0.7 0.7 0.7 1</diffuse>
          <specular>0.01 0.01 0.01 1</specular>
          <emissive>0 0 0 1</emissive>
        </material>
        <transparency>0</transparency>
        <cast_shadows>1</cast_shadows>
      </visual>
    </link>
    <joint name='link_4_baselink_JOINT_0' type='fixed'>
      <parent>base_link</parent>
      <child>link_4</child>
      <pose>0 0 0 0 -0 0</pose>
    </joint>

    <joint name='base_link_JOINT_link_1' type='fixed'>
      <parent>base_link</parent>
      <child>link_1</child>
      <pose>0 0 0 0 -0 0</pose>
    </joint>
    <joint name='base_link_JOINT_link_2' type='revolute'>
      <parent>base_link</parent>
      <child>link_2</child>
      <pose>0 0 0 0 -0 0</pose>
      <axis>
        <xyz>0 1 0</xyz>
        <limit>
          <lower>-0.349</lower>
          <upper>0.349</upper>
          <effort>-1</effort>
          <velocity>-1</velocity>
        </limit>
        <dynamics>
          <spring_reference>0</spring_reference>
          <spring_stiffness>0</spring_stiffness>
          <damping>0.01</damping>
        </dynamics>
      </axis>
      <physics>
        <ode>
          <implicit_spring_damper>1</implicit_spring_damper>
        </ode>
      </physics>
    </joint>
    <joint name='base_link_JOINT_link_3' type='revolute'>
      <parent>base_link</parent>
      <child>link_3</child>
      <pose>0 0 0 0 -0 0</pose>
      <axis>
        <xyz>0 1 0</xyz>
        <limit>
          <lower>-0.349</lower>
          <upper>0.349</upper>
          <effort>-1</effort>
          <velocity>-1</velocity>
        </limit>
        <dynamics>
          <spring_reference>0</spring_reference>
          <spring_stiffness>0</spring_stiffness>
          <damping>0.01</damping>
        </dynamics>
      </axis>
      <physics>
        <ode>
          <implicit_spring_damper>1</implicit_spring_damper>
        </ode>
      </physics>
    </joint>
    <link name='rotor_01'>
      <pose>0.0 0.2 0.11 0 0 0</pose>
      <inertial>
        <pose>0 0 0 0 0 0</pose>
        <mass>0.005</mass>
        <inertia>
          <ixx>9.75e-08</ixx>
          <ixy>0</ixy>
          <ixz>0</ixz>
          <iyy>0.0000273104</iyy>
          <iyz>0</iyz>
          <izz>0.0000274004</izz>
        </inertia>
      </inertial>
      <visual name='rotor_0_visual'>
        <pose>0 0 0 0 0 0</pose>
        <geometry>
          <mesh>
            <scale>1 1 1</scale>
            <uri>model://flyant/meshes/iris_prop_ccw.dae</uri>
          </mesh>
        </geometry>
        <material>
          <script>
            <name>Gazebo/Blue</name>
            <uri>file://media/materials/scripts/gazebo.material</uri>
          </script>
        </material>
      </visual>
      <gravity>1</gravity>
      <velocity_decay/>
    </link>
    <joint name='rotor_01_joint' type='revolute'>
      <child>rotor_01</child>
      <parent>link_2</parent>
      <axis>
        <xyz>0 0 1</xyz>
        <limit>
          <lower>-1e+16</lower>
          <upper>1e+16</upper>
        </limit>
        <dynamics>
          <spring_reference>0</spring_reference>
          <spring_stiffness>0</spring_stiffness>
          <damping>0.0001</damping>
          <friction>0</friction>
        </dynamics>
        <use_parent_model_frame>0</use_parent_model_frame>
      </axis>
    </joint>
    <link name='rotor_11'>
      <pose>0.0 -0.2 0.11 0 0 0</pose>
      <inertial>
        <pose>0 0 0 0 0 0</pose>
        <mass>0.005</mass>
        <inertia>
          <ixx>9.75e-08</ixx>
          <ixy>0</ixy>
          <ixz>0</ixz>
          <iyy>0.0000273104</iyy>
          <iyz>0</iyz>
          <izz>0.0000274004</izz>
        </inertia>
      </inertial>
      <visual name='rotor_2_visual'>
        <pose>0 0 0 0 0 0</pose>
        <geometry>
          <mesh>
            <scale>1 1 1</scale>
            <uri>model://flyant/meshes/iris_prop_cw.dae</uri>
          </mesh>
        </geometry>
        <material>
          <script>
            <name>Gazebo/Blue</name>
            <uri>file://media/materials/scripts/gazebo.material</uri>
          </script>
        </material>
      </visual>
      <gravity>1</gravity>
      <velocity_decay/>
    </link>
    <joint name='rotor_11_joint' type='revolute'>
      <child>rotor_11</child>
      <parent>link_3</parent>
      <axis>
        <xyz>0 0 1</xyz>
        <limit>
          <lower>-1e+16</lower>
          <upper>1e+16</upper>
        </limit>
        <dynamics>
          <spring_reference>0</spring_reference>
          <spring_stiffness>0</spring_stiffness>
          <damping>0.0001</damping>
          <friction>0</friction>
        </dynamics>
        <use_parent_model_frame>1</use_parent_model_frame>
      </axis>
    </joint>
    <include>
      <uri>model://imu</uri>
      <pose>0 0 0 0 0 0</pose>
      <name>imu</name>
    </include>
    <joint name='imu_joint' type='revolute'>
      <child>imu::link</child>
      <parent>base_link</parent>
      <axis>
        <xyz>1 0 0</xyz>
        <limit>
          <lower>0</lower>
          <upper>0</upper>
          <effort>0</effort>
          <velocity>0</velocity>
        </limit>
        <dynamics>
          <spring_reference>0</spring_reference>
          <spring_stiffness>0</spring_stiffness>
        </dynamics>
        <use_parent_model_frame>1</use_parent_model_frame>
      </axis>
    </joint>
    <plugin name='rosbag' filename='libgazebo_multirotor_base_plugin.so'>
      <robotNamespace/>
      <linkName>base_link</linkName>
      <rotorVelocitySlowdownSim>10</rotorVelocitySlowdownSim>
    </plugin>

    <plugin name='rotor4_plugin' filename='libgazebo_motor_model.so'>
      <robotNamespace/>
      <jointName>rotor_01_joint</jointName>
      <linkName>rotor_01</linkName>
      <turningDirection>ccw</turningDirection>
      <timeConstantUp>0.0125</timeConstantUp>
      <timeConstantDown>0.025</timeConstantDown>
      <maxRotVelocity>2000</maxRotVelocity>
      <motorConstant>9.84e-06</motorConstant>
      <momentConstant>0.06</momentConstant>
      <commandSubTopic>/gazebo/command/motor_speed</commandSubTopic>
      <motorNumber>0</motorNumber>
      <rotorDragCoefficient>0.000175</rotorDragCoefficient>
      <rollingMomentCoefficient>1e-06</rollingMomentCoefficient>
      <motorSpeedPubTopic>/motor_speed/0</motorSpeedPubTopic>
      <rotorVelocitySlowdownSim>10</rotorVelocitySlowdownSim>
    </plugin>
    <plugin name='rotor5_plugin' filename='libgazebo_motor_model.so'>
      <robotNamespace/>
      <jointName>rotor_11_joint</jointName>
      <linkName>rotor_11</linkName>
      <turningDirection>cw</turningDirection>
      <timeConstantUp>0.0125</timeConstantUp>
      <timeConstantDown>0.025</timeConstantDown>
      <maxRotVelocity>2000</maxRotVelocity>
      <motorConstant>9.84e-06</motorConstant>
      <momentConstant>0.06</momentConstant>
      <commandSubTopic>/gazebo/command/motor_speed</commandSubTopic>
      <motorNumber>1</motorNumber>
      <rotorDragCoefficient>0.000175</rotorDragCoefficient>
      <rollingMomentCoefficient>1e-06</rollingMomentCoefficient>
      <motorSpeedPubTopic>/motor_speed/1</motorSpeedPubTopic>
      <rotorVelocitySlowdownSim>10</rotorVelocitySlowdownSim>
    </plugin>
    <include>
      <uri>model://gps</uri>
      <pose>0.04 0 0.05 0 0 0</pose>
      <name>gps0</name>
    </include>
    <joint name='gps0_joint' type='fixed'>
      <child>gps0::link</child>
      <parent>base_link</parent>
    </joint>
    <include>
      <uri>model://magnetometer</uri>
      <pose>0 0 0 0 0 0</pose>
      <name>mag</name>
    </include>
    <joint name='mag_joint' type='fixed'>
      <child>mag::link</child>
      <parent>base_link</parent>
    </joint>
    <plugin name='groundtruth_plugin' filename='libgazebo_groundtruth_plugin.so'>
      <robotNamespace/>
    </plugin>
    <plugin name='barometer_plugin' filename='libgazebo_barometer_plugin.so'>
      <robotNamespace/>
      <pubRate>50</pubRate>
      <baroTopic>/baro</baroTopic>
      <baroDriftPaPerSec>0</baroDriftPaPerSec>
    </plugin>
    <plugin name='mavlink_interface' filename='libgazebo_mavlink_interface.so'>
      <robotNamespace/>
      <imuSubTopic>/imu</imuSubTopic>
      <magSubTopic>/mag</magSubTopic>
      <baroSubTopic>/baro</baroSubTopic>
      <mavlink_addr>INADDR_ANY</mavlink_addr>
      <mavlink_tcp_port>{{ mavlink_tcp_port }}</mavlink_tcp_port>
      <mavlink_udp_port>{{ mavlink_udp_port }}</mavlink_udp_port>
      <serialEnabled>{{ serial_enabled }}</serialEnabled>
      <serialDevice>{{ serial_device }}</serialDevice>
      <baudRate>{{ serial_baudrate }}</baudRate>
      <qgc_addr>INADDR_ANY</qgc_addr>
      <qgc_udp_port>14550</qgc_udp_port>
      <sdk_addr>INADDR_ANY</sdk_addr>
      <sdk_udp_port>14540</sdk_udp_port>
      <hil_mode>{{ hil_mode }}</hil_mode>
      <hil_state_level>0</hil_state_level>
      <send_vision_estimation>0</send_vision_estimation>
      <send_odometry>1</send_odometry>
      <enable_lockstep>1</enable_lockstep>
      <use_tcp>1</use_tcp>
      <motorSpeedCommandPubTopic>/gazebo/command/motor_speed</motorSpeedCommandPubTopic>
      <control_channels>
        <channel name='rotor5'>
          <input_index>0</input_index>
          <input_offset>0</input_offset>
          <input_scaling>2000</input_scaling>
          <zero_position_disarmed>0</zero_position_disarmed>
          <zero_position_armed>100</zero_position_armed>
          <joint_control_type>velocity</joint_control_type>
        </channel>
        <channel name='rotor6'>
          <input_index>1</input_index>
          <input_offset>0</input_offset>
          <input_scaling>2000</input_scaling>
          <zero_position_disarmed>0</zero_position_disarmed>
          <zero_position_armed>100</zero_position_armed>
          <joint_control_type>velocity</joint_control_type>
        </channel>
        <channel name="u1">
          <input_index>2</input_index>
          <input_offset>0</input_offset>
          <input_scaling>0.5</input_scaling>
          <zero_position_disarmed>0</zero_position_disarmed>
          <zero_position_armed>0</zero_position_armed>
          <joint_control_type>position</joint_control_type>
          <joint_name>base_link_JOINT_link_2</joint_name>
          <joint_control_pid>
            <p>0.5</p>
            <i>0</i>
            <d>0</d>
            <iMax>0</iMax>
            <iMin>0</iMin>
            <cmdMax>20</cmdMax>
            <cmdMin>-20</cmdMin>
          </joint_control_pid>
        </channel>
        <channel name="u2">
          <input_index>3</input_index>
          <input_offset>0</input_offset>
          <input_scaling>0.5</input_scaling>
          <zero_position_disarmed>0</zero_position_disarmed>
          <zero_position_armed>0</zero_position_armed>
          <joint_control_type>position</joint_control_type>
          <joint_name>base_link_JOINT_link_3</joint_name>
          <joint_control_pid>
            <p>0.5</p>
            <i>0</i>
            <d>0</d>
            <iMax>0</iMax>
            <iMin>0</iMin>
            <cmdMax>20</cmdMax>
            <cmdMin>-20</cmdMin>
          </joint_control_pid>
        </channel>
      </control_channels>
    </plugin>
    <static>0</static>
  </model>
</sdf>
